
31/07/2020 11:40:30 - index 93 is out of bounds for axis 0 with size 4
Traceback (most recent call last):
  File "/Users/jburnsky/Documents/GitHub/Crow/Crow_GC/Pull_GC.py", line 121, in pulldatacallback
    self.datalist[int(temp[C.globals_GC.welltarg[0]][C.globals_GC.welltarg[1]].text)-1, i] = str(keep).replace("\"", "").replace("]", "").replace("[", "")
IndexError: index 93 is out of bounds for axis 0 with size 4


31/07/2020 11:40:33 - index 94 is out of bounds for axis 0 with size 4
Traceback (most recent call last):
  File "/Users/jburnsky/Documents/GitHub/Crow/Crow_GC/Pull_GC.py", line 121, in pulldatacallback
    self.datalist[int(temp[C.globals_GC.welltarg[0]][C.globals_GC.welltarg[1]].text)-1, i] = str(keep).replace("\"", "").replace("]", "").replace("[", "")
IndexError: index 94 is out of bounds for axis 0 with size 4


31/07/2020 11:40:33 - index 95 is out of bounds for axis 0 with size 4
Traceback (most recent call last):
  File "/Users/jburnsky/Documents/GitHub/Crow/Crow_GC/Pull_GC.py", line 121, in pulldatacallback
    self.datalist[int(temp[C.globals_GC.welltarg[0]][C.globals_GC.welltarg[1]].text)-1, i] = str(keep).replace("\"", "").replace("]", "").replace("[", "")
IndexError: index 95 is out of bounds for axis 0 with size 4


31/07/2020 11:40:42 - index 93 is out of bounds for axis 0 with size 4
Traceback (most recent call last):
  File "/Users/jburnsky/Documents/GitHub/Crow/Crow_GC/Pull_GC.py", line 121, in pulldatacallback
    self.datalist[int(temp[C.globals_GC.welltarg[0]][C.globals_GC.welltarg[1]].text)-1, i] = str(keep).replace("\"", "").replace("]", "").replace("[", "")
IndexError: index 93 is out of bounds for axis 0 with size 4


31/07/2020 11:40:44 - index 94 is out of bounds for axis 0 with size 4
Traceback (most recent call last):
  File "/Users/jburnsky/Documents/GitHub/Crow/Crow_GC/Pull_GC.py", line 121, in pulldatacallback
    self.datalist[int(temp[C.globals_GC.welltarg[0]][C.globals_GC.welltarg[1]].text)-1, i] = str(keep).replace("\"", "").replace("]", "").replace("[", "")
IndexError: index 94 is out of bounds for axis 0 with size 4


31/07/2020 11:40:44 - index 95 is out of bounds for axis 0 with size 4
Traceback (most recent call last):
  File "/Users/jburnsky/Documents/GitHub/Crow/Crow_GC/Pull_GC.py", line 121, in pulldatacallback
    self.datalist[int(temp[C.globals_GC.welltarg[0]][C.globals_GC.welltarg[1]].text)-1, i] = str(keep).replace("\"", "").replace("]", "").replace("[", "")
IndexError: index 95 is out of bounds for axis 0 with size 4


31/07/2020 11:41:46 - index 6 is out of bounds for axis 0 with size 6
Traceback (most recent call last):
  File "/Users/jburnsky/Documents/GitHub/Crow/Crow_GC/Pull_GC.py", line 121, in pulldatacallback
    self.datalist[int(temp[C.globals_GC.welltarg[0]][C.globals_GC.welltarg[1]].text)-1, i] = str(keep).replace("\"", "").replace("]", "").replace("[", "")
IndexError: index 6 is out of bounds for axis 0 with size 6


31/07/2020 11:41:47 - index 7 is out of bounds for axis 0 with size 6
Traceback (most recent call last):
  File "/Users/jburnsky/Documents/GitHub/Crow/Crow_GC/Pull_GC.py", line 121, in pulldatacallback
    self.datalist[int(temp[C.globals_GC.welltarg[0]][C.globals_GC.welltarg[1]].text)-1, i] = str(keep).replace("\"", "").replace("]", "").replace("[", "")
IndexError: index 7 is out of bounds for axis 0 with size 6


31/07/2020 11:44:01 - index 3 is out of bounds for axis 0 with size 3
Traceback (most recent call last):
  File "/Users/jburnsky/Documents/GitHub/Crow/Crow_GC/Pull_GC.py", line 121, in pulldatacallback
    self.datalist[int(temp[C.globals_GC.welltarg[0]][C.globals_GC.welltarg[1]].text)-1, i] = str(keep).replace("\"", "").replace("]", "").replace("[", "")
IndexError: index 3 is out of bounds for axis 0 with size 3


31/07/2020 11:44:05 - index 4 is out of bounds for axis 0 with size 3
Traceback (most recent call last):
  File "/Users/jburnsky/Documents/GitHub/Crow/Crow_GC/Pull_GC.py", line 121, in pulldatacallback
    self.datalist[int(temp[C.globals_GC.welltarg[0]][C.globals_GC.welltarg[1]].text)-1, i] = str(keep).replace("\"", "").replace("]", "").replace("[", "")
IndexError: index 4 is out of bounds for axis 0 with size 3


31/07/2020 11:59:41 - index 4 is out of bounds for axis 0 with size 4
Traceback (most recent call last):
  File "/Users/jburnsky/Documents/GitHub/Crow/Crow_GC/Pull_GC.py", line 122, in pulldatacallback
    self.datalist[int(temp[C.globals_GC.welltarg[0]][C.globals_GC.welltarg[1]].text)-1, i] = str(keep).replace("\"", "").replace("]", "").replace("[", "")
IndexError: index 4 is out of bounds for axis 0 with size 4


31/07/2020 11:59:46 - index 5 is out of bounds for axis 0 with size 4
Traceback (most recent call last):
  File "/Users/jburnsky/Documents/GitHub/Crow/Crow_GC/Pull_GC.py", line 122, in pulldatacallback
    self.datalist[int(temp[C.globals_GC.welltarg[0]][C.globals_GC.welltarg[1]].text)-1, i] = str(keep).replace("\"", "").replace("]", "").replace("[", "")
IndexError: index 5 is out of bounds for axis 0 with size 4

